src/main/resources/input/orders_1.txt
#1 09:45 BAC buy 100 240.10
#2 09:45 BAC sell 90 237.45
#3 09:47 BAC sell 80 238.10
#5 09:48 BAC buy 220 241.50
#6 09:49 BAC sell 50 238.50
#7 09:52 TCS sell 10 1001.10
#8 10:01 BAC sell 20 240.10
#9 10:02 BAC sell 150 242.70

#10 10:04 BAC buy 120 240.10
#11 10:09 BAC buy 90 237.45
#12 10:10 BAC sell 80 238.10
#13 10:12 BAC sell 220 241.50
#14 10:15 BAC sell 50 238.50
#15 10:20 TCS buy 10 1001.10
#16 10:21 BAC sell 20 240.10
#17 10:22 BAC sell 150 242.70

#18 10:25 BAC buy 120 240.10
#19 10:30 BAC buy 90 237.45
#20 10:32 BAC sell 80 238.10
#21 10:35 BAC sell 220 241.50
#22 10:36 BAC sell 60 238.50
#23 10:38 TCS buy 10 1001.10
#24 10:40 BAC sell 20 240.10
#25 10:41 BAC sell 150 242.70
