src/main/resources/input/sell_orders.txt
#1 09:45 BAC sell 100 240.10
#2 09:45 BAC sell 90 237.45
#3 09:47 BAC sell 80 238.10
#5 09:48 BAC sell 220 241.50
#6 09:49 BAC sell 50 238.50
#7 09:52 TCS sell 10 1001.10
#8 10:01 BAC sell 20 240.10
#9 10:02 BAC sell 150 242.70
